[2021-03-07 19:29:04,716] {taskinstance.py:851} INFO - Dependencies all met for <TaskInstance: check_minio_1.check_s3_for_file_in_s3 2021-03-06T00:00:00+00:00 [queued]>
[2021-03-07 19:29:04,727] {taskinstance.py:851} INFO - Dependencies all met for <TaskInstance: check_minio_1.check_s3_for_file_in_s3 2021-03-06T00:00:00+00:00 [queued]>
[2021-03-07 19:29:04,727] {taskinstance.py:1042} INFO - 
--------------------------------------------------------------------------------
[2021-03-07 19:29:04,727] {taskinstance.py:1043} INFO - Starting attempt 1 of 1
[2021-03-07 19:29:04,727] {taskinstance.py:1044} INFO - 
--------------------------------------------------------------------------------
[2021-03-07 19:29:04,733] {taskinstance.py:1063} INFO - Executing <Task(S3KeySensor): check_s3_for_file_in_s3> on 2021-03-06T00:00:00+00:00
[2021-03-07 19:29:04,737] {standard_task_runner.py:52} INFO - Started process 50 to run task
[2021-03-07 19:29:04,739] {standard_task_runner.py:76} INFO - Running: ['airflow', 'tasks', 'run', 'check_minio_1', 'check_s3_for_file_in_s3', '2021-03-06T00:00:00+00:00', '--job-id', '174', '--pool', 'default_pool', '--raw', '--subdir', 'DAGS_FOLDER/check_minio_1/main.py', '--cfg-path', '/tmp/tmpu_x3k8ml', '--error-file', '/tmp/tmp1y5ee_go']
[2021-03-07 19:29:04,740] {standard_task_runner.py:77} INFO - Job 174: Subtask check_s3_for_file_in_s3
[2021-03-07 19:29:04,767] {logging_mixin.py:104} INFO - Running <TaskInstance: check_minio_1.check_s3_for_file_in_s3 2021-03-06T00:00:00+00:00 [running]> on host 020f66ce59e6
[2021-03-07 19:29:04,796] {taskinstance.py:1257} INFO - Exporting the following env vars:
AIRFLOW_CTX_DAG_OWNER=iotoi
AIRFLOW_CTX_DAG_ID=check_minio_1
AIRFLOW_CTX_TASK_ID=check_s3_for_file_in_s3
AIRFLOW_CTX_EXECUTION_DATE=2021-03-06T00:00:00+00:00
AIRFLOW_CTX_DAG_RUN_ID=scheduled__2021-03-06T00:00:00+00:00
[2021-03-07 19:29:04,796] {s3_key.py:98} INFO - Poking for key : s3://my-first-bucket/*
[2021-03-07 19:29:04,797] {base_aws.py:362} INFO - Airflow Connection: aws_conn_id=local_minio
[2021-03-07 19:29:04,803] {base_aws.py:164} INFO - Credentials retrieved from extra_config
[2021-03-07 19:29:04,803] {base_aws.py:81} INFO - Creating session with aws_access_key_id=minio-access-key region_name=None
[2021-03-07 19:29:04,815] {base_aws.py:151} INFO - role_arn is None
[2021-03-07 19:29:15,862] {taskinstance.py:1455} ERROR - Could not connect to the endpoint URL: "http://192.168.0.9:9000/my-first-bucket?list-type=2&prefix=&delimiter=&encoding-type=url"
Traceback (most recent call last):
  File "/home/airflow/.local/lib/python3.6/site-packages/urllib3/connection.py", line 160, in _new_conn
    (self._dns_host, self.port), self.timeout, **extra_kw
  File "/home/airflow/.local/lib/python3.6/site-packages/urllib3/util/connection.py", line 84, in create_connection
    raise err
  File "/home/airflow/.local/lib/python3.6/site-packages/urllib3/util/connection.py", line 74, in create_connection
    sock.connect(sa)
ConnectionRefusedError: [Errno 111] Connection refused

During handling of the above exception, another exception occurred:

Traceback (most recent call last):
  File "/home/airflow/.local/lib/python3.6/site-packages/botocore/httpsession.py", line 263, in send
    chunked=self._chunked(request.headers),
  File "/home/airflow/.local/lib/python3.6/site-packages/urllib3/connectionpool.py", line 727, in urlopen
    method, url, error=e, _pool=self, _stacktrace=sys.exc_info()[2]
  File "/home/airflow/.local/lib/python3.6/site-packages/urllib3/util/retry.py", line 386, in increment
    raise six.reraise(type(error), error, _stacktrace)
  File "/home/airflow/.local/lib/python3.6/site-packages/urllib3/packages/six.py", line 735, in reraise
    raise value
  File "/home/airflow/.local/lib/python3.6/site-packages/urllib3/connectionpool.py", line 677, in urlopen
    chunked=chunked,
  File "/home/airflow/.local/lib/python3.6/site-packages/urllib3/connectionpool.py", line 392, in _make_request
    conn.request(method, url, **httplib_request_kw)
  File "/usr/local/lib/python3.6/http/client.py", line 1287, in request
    self._send_request(method, url, body, headers, encode_chunked)
  File "/home/airflow/.local/lib/python3.6/site-packages/botocore/awsrequest.py", line 92, in _send_request
    method, url, body, headers, *args, **kwargs)
  File "/usr/local/lib/python3.6/http/client.py", line 1333, in _send_request
    self.endheaders(body, encode_chunked=encode_chunked)
  File "/usr/local/lib/python3.6/http/client.py", line 1282, in endheaders
    self._send_output(message_body, encode_chunked=encode_chunked)
  File "/home/airflow/.local/lib/python3.6/site-packages/botocore/awsrequest.py", line 119, in _send_output
    self.send(msg)
  File "/home/airflow/.local/lib/python3.6/site-packages/botocore/awsrequest.py", line 203, in send
    return super(AWSConnection, self).send(str)
  File "/usr/local/lib/python3.6/http/client.py", line 980, in send
    self.connect()
  File "/home/airflow/.local/lib/python3.6/site-packages/urllib3/connection.py", line 187, in connect
    conn = self._new_conn()
  File "/home/airflow/.local/lib/python3.6/site-packages/urllib3/connection.py", line 172, in _new_conn
    self, "Failed to establish a new connection: %s" % e
urllib3.exceptions.NewConnectionError: <botocore.awsrequest.AWSHTTPConnection object at 0x7f0be1475f60>: Failed to establish a new connection: [Errno 111] Connection refused

During handling of the above exception, another exception occurred:

Traceback (most recent call last):
  File "/home/airflow/.local/lib/python3.6/site-packages/airflow/models/taskinstance.py", line 1112, in _run_raw_task
    self._prepare_and_execute_task_with_callbacks(context, task)
  File "/home/airflow/.local/lib/python3.6/site-packages/airflow/models/taskinstance.py", line 1285, in _prepare_and_execute_task_with_callbacks
    result = self._execute_task(context, task_copy)
  File "/home/airflow/.local/lib/python3.6/site-packages/airflow/models/taskinstance.py", line 1315, in _execute_task
    result = task_copy.execute(context=context)
  File "/home/airflow/.local/lib/python3.6/site-packages/airflow/sensors/base.py", line 228, in execute
    while not self.poke(context):
  File "/home/airflow/.local/lib/python3.6/site-packages/airflow/providers/amazon/aws/sensors/s3_key.py", line 100, in poke
    return self.get_hook().check_for_wildcard_key(self.bucket_key, self.bucket_name)
  File "/home/airflow/.local/lib/python3.6/site-packages/airflow/providers/amazon/aws/hooks/s3.py", line 61, in wrapper
    return func(*bound_args.args, **bound_args.kwargs)
  File "/home/airflow/.local/lib/python3.6/site-packages/airflow/providers/amazon/aws/hooks/s3.py", line 90, in wrapper
    return func(*bound_args.args, **bound_args.kwargs)
  File "/home/airflow/.local/lib/python3.6/site-packages/airflow/providers/amazon/aws/hooks/s3.py", line 427, in check_for_wildcard_key
    self.get_wildcard_key(wildcard_key=wildcard_key, bucket_name=bucket_name, delimiter=delimiter)
  File "/home/airflow/.local/lib/python3.6/site-packages/airflow/providers/amazon/aws/hooks/s3.py", line 61, in wrapper
    return func(*bound_args.args, **bound_args.kwargs)
  File "/home/airflow/.local/lib/python3.6/site-packages/airflow/providers/amazon/aws/hooks/s3.py", line 90, in wrapper
    return func(*bound_args.args, **bound_args.kwargs)
  File "/home/airflow/.local/lib/python3.6/site-packages/airflow/providers/amazon/aws/hooks/s3.py", line 449, in get_wildcard_key
    key_list = self.list_keys(bucket_name, prefix=prefix, delimiter=delimiter)
  File "/home/airflow/.local/lib/python3.6/site-packages/airflow/providers/amazon/aws/hooks/s3.py", line 61, in wrapper
    return func(*bound_args.args, **bound_args.kwargs)
  File "/home/airflow/.local/lib/python3.6/site-packages/airflow/providers/amazon/aws/hooks/s3.py", line 293, in list_keys
    for page in response:
  File "/home/airflow/.local/lib/python3.6/site-packages/botocore/paginate.py", line 255, in __iter__
    response = self._make_request(current_kwargs)
  File "/home/airflow/.local/lib/python3.6/site-packages/botocore/paginate.py", line 332, in _make_request
    return self._method(**current_kwargs)
  File "/home/airflow/.local/lib/python3.6/site-packages/botocore/client.py", line 357, in _api_call
    return self._make_api_call(operation_name, kwargs)
  File "/home/airflow/.local/lib/python3.6/site-packages/botocore/client.py", line 663, in _make_api_call
    operation_model, request_dict, request_context)
  File "/home/airflow/.local/lib/python3.6/site-packages/botocore/client.py", line 682, in _make_request
    return self._endpoint.make_request(operation_model, request_dict)
  File "/home/airflow/.local/lib/python3.6/site-packages/botocore/endpoint.py", line 102, in make_request
    return self._send_request(request_dict, operation_model)
  File "/home/airflow/.local/lib/python3.6/site-packages/botocore/endpoint.py", line 137, in _send_request
    success_response, exception):
  File "/home/airflow/.local/lib/python3.6/site-packages/botocore/endpoint.py", line 256, in _needs_retry
    caught_exception=caught_exception, request_dict=request_dict)
  File "/home/airflow/.local/lib/python3.6/site-packages/botocore/hooks.py", line 356, in emit
    return self._emitter.emit(aliased_event_name, **kwargs)
  File "/home/airflow/.local/lib/python3.6/site-packages/botocore/hooks.py", line 228, in emit
    return self._emit(event_name, kwargs)
  File "/home/airflow/.local/lib/python3.6/site-packages/botocore/hooks.py", line 211, in _emit
    response = handler(**kwargs)
  File "/home/airflow/.local/lib/python3.6/site-packages/botocore/retryhandler.py", line 183, in __call__
    if self._checker(attempts, response, caught_exception):
  File "/home/airflow/.local/lib/python3.6/site-packages/botocore/retryhandler.py", line 251, in __call__
    caught_exception)
  File "/home/airflow/.local/lib/python3.6/site-packages/botocore/retryhandler.py", line 277, in _should_retry
    return self._checker(attempt_number, response, caught_exception)
  File "/home/airflow/.local/lib/python3.6/site-packages/botocore/retryhandler.py", line 317, in __call__
    caught_exception)
  File "/home/airflow/.local/lib/python3.6/site-packages/botocore/retryhandler.py", line 223, in __call__
    attempt_number, caught_exception)
  File "/home/airflow/.local/lib/python3.6/site-packages/botocore/retryhandler.py", line 359, in _check_caught_exception
    raise caught_exception
  File "/home/airflow/.local/lib/python3.6/site-packages/botocore/endpoint.py", line 200, in _do_get_response
    http_response = self._send(request)
  File "/home/airflow/.local/lib/python3.6/site-packages/botocore/endpoint.py", line 269, in _send
    return self.http_session.send(request)
  File "/home/airflow/.local/lib/python3.6/site-packages/botocore/httpsession.py", line 283, in send
    raise EndpointConnectionError(endpoint_url=request.url, error=e)
botocore.exceptions.EndpointConnectionError: Could not connect to the endpoint URL: "http://192.168.0.9:9000/my-first-bucket?list-type=2&prefix=&delimiter=&encoding-type=url"
[2021-03-07 19:29:15,868] {taskinstance.py:1503} INFO - Marking task as FAILED. dag_id=check_minio_1, task_id=check_s3_for_file_in_s3, execution_date=20210306T000000, start_date=20210307T192904, end_date=20210307T192915
[2021-03-07 19:29:15,922] {local_task_job.py:146} INFO - Task exited with return code 1
