[2021-03-03 21:12:44,425] {taskinstance.py:851} INFO - Dependencies all met for <TaskInstance: save_to_minio_2.write_text_file 2021-03-03T21:12:43.813335+00:00 [queued]>
[2021-03-03 21:12:44,438] {taskinstance.py:851} INFO - Dependencies all met for <TaskInstance: save_to_minio_2.write_text_file 2021-03-03T21:12:43.813335+00:00 [queued]>
[2021-03-03 21:12:44,438] {taskinstance.py:1042} INFO - 
--------------------------------------------------------------------------------
[2021-03-03 21:12:44,438] {taskinstance.py:1043} INFO - Starting attempt 1 of 1
[2021-03-03 21:12:44,438] {taskinstance.py:1044} INFO - 
--------------------------------------------------------------------------------
[2021-03-03 21:12:44,444] {taskinstance.py:1063} INFO - Executing <Task(_PythonDecoratedOperator): write_text_file> on 2021-03-03T21:12:43.813335+00:00
[2021-03-03 21:12:44,449] {standard_task_runner.py:52} INFO - Started process 48 to run task
[2021-03-03 21:12:44,451] {standard_task_runner.py:76} INFO - Running: ['airflow', 'tasks', 'run', 'save_to_minio_2', 'write_text_file', '2021-03-03T21:12:43.813335+00:00', '--job-id', '49', '--pool', 'default_pool', '--raw', '--subdir', 'DAGS_FOLDER/save_to_mino_2/main.py', '--cfg-path', '/tmp/tmpnee8xi4r', '--error-file', '/tmp/tmp15rlj1qc']
[2021-03-03 21:12:44,451] {standard_task_runner.py:77} INFO - Job 49: Subtask write_text_file
[2021-03-03 21:12:44,475] {logging_mixin.py:104} INFO - Running <TaskInstance: save_to_minio_2.write_text_file 2021-03-03T21:12:43.813335+00:00 [running]> on host 4c61e128b408
[2021-03-03 21:12:44,506] {taskinstance.py:1257} INFO - Exporting the following env vars:
AIRFLOW_CTX_DAG_OWNER=iotoi
AIRFLOW_CTX_DAG_ID=save_to_minio_2
AIRFLOW_CTX_TASK_ID=write_text_file
AIRFLOW_CTX_EXECUTION_DATE=2021-03-03T21:12:43.813335+00:00
AIRFLOW_CTX_DAG_RUN_ID=manual__2021-03-03T21:12:43.813335+00:00
[2021-03-03 21:12:44,507] {base_aws.py:362} INFO - Airflow Connection: aws_conn_id=local_minio
[2021-03-03 21:12:44,513] {base_aws.py:164} INFO - Credentials retrieved from extra_config
[2021-03-03 21:12:44,513] {base_aws.py:81} INFO - Creating session with aws_access_key_id=minio-access-key region_name=None
[2021-03-03 21:12:44,522] {base_aws.py:151} INFO - role_arn is None
[2021-03-03 21:12:44,557] {taskinstance.py:1455} ERROR - The key my-test-file.txt already exists.
Traceback (most recent call last):
  File "/home/airflow/.local/lib/python3.6/site-packages/airflow/models/taskinstance.py", line 1112, in _run_raw_task
    self._prepare_and_execute_task_with_callbacks(context, task)
  File "/home/airflow/.local/lib/python3.6/site-packages/airflow/models/taskinstance.py", line 1285, in _prepare_and_execute_task_with_callbacks
    result = self._execute_task(context, task_copy)
  File "/home/airflow/.local/lib/python3.6/site-packages/airflow/models/taskinstance.py", line 1315, in _execute_task
    result = task_copy.execute(context=context)
  File "/home/airflow/.local/lib/python3.6/site-packages/airflow/operators/python.py", line 233, in execute
    return_value = self.python_callable(*self.op_args, **self.op_kwargs)
  File "/opt/airflow/dags/save_to_mino_2/main.py", line 47, in write_text_file
    "/tmp/test.txt", key="my-test-file.txt", bucket_name="my-first-bucket"
  File "/home/airflow/.local/lib/python3.6/site-packages/airflow/providers/amazon/aws/hooks/s3.py", line 61, in wrapper
    return func(*bound_args.args, **bound_args.kwargs)
  File "/home/airflow/.local/lib/python3.6/site-packages/airflow/providers/amazon/aws/hooks/s3.py", line 90, in wrapper
    return func(*bound_args.args, **bound_args.kwargs)
  File "/home/airflow/.local/lib/python3.6/site-packages/airflow/providers/amazon/aws/hooks/s3.py", line 490, in load_file
    raise ValueError(f"The key {key} already exists.")
ValueError: The key my-test-file.txt already exists.
[2021-03-03 21:12:44,558] {taskinstance.py:1503} INFO - Marking task as FAILED. dag_id=save_to_minio_2, task_id=write_text_file, execution_date=20210303T211243, start_date=20210303T211244, end_date=20210303T211244
[2021-03-03 21:12:44,584] {local_task_job.py:146} INFO - Task exited with return code 1
