[2021-03-03 21:08:22,698] {taskinstance.py:851} INFO - Dependencies all met for <TaskInstance: save_to_minio.generate_and_upload_to_s3 2020-01-13T00:00:00+00:00 [queued]>
[2021-03-03 21:08:22,708] {taskinstance.py:851} INFO - Dependencies all met for <TaskInstance: save_to_minio.generate_and_upload_to_s3 2020-01-13T00:00:00+00:00 [queued]>
[2021-03-03 21:08:22,708] {taskinstance.py:1042} INFO - 
--------------------------------------------------------------------------------
[2021-03-03 21:08:22,708] {taskinstance.py:1043} INFO - Starting attempt 2 of 2
[2021-03-03 21:08:22,708] {taskinstance.py:1044} INFO - 
--------------------------------------------------------------------------------
[2021-03-03 21:08:22,713] {taskinstance.py:1063} INFO - Executing <Task(PythonOperator): generate_and_upload_to_s3> on 2020-01-13T00:00:00+00:00
[2021-03-03 21:08:22,717] {standard_task_runner.py:52} INFO - Started process 50 to run task
[2021-03-03 21:08:22,719] {standard_task_runner.py:76} INFO - Running: ['airflow', 'tasks', 'run', 'save_to_minio', 'generate_and_upload_to_s3', '2020-01-13T00:00:00+00:00', '--job-id', '45', '--pool', 'default_pool', '--raw', '--subdir', 'DAGS_FOLDER/save_to_minio/main.py', '--cfg-path', '/tmp/tmp0c9i6uaq', '--error-file', '/tmp/tmpxev_1__a']
[2021-03-03 21:08:22,719] {standard_task_runner.py:77} INFO - Job 45: Subtask generate_and_upload_to_s3
[2021-03-03 21:08:22,742] {logging_mixin.py:104} INFO - Running <TaskInstance: save_to_minio.generate_and_upload_to_s3 2020-01-13T00:00:00+00:00 [running]> on host 4c61e128b408
[2021-03-03 21:08:22,763] {taskinstance.py:1257} INFO - Exporting the following env vars:
AIRFLOW_CTX_DAG_EMAIL=airflow@example.com
AIRFLOW_CTX_DAG_OWNER=iotoi
AIRFLOW_CTX_DAG_ID=save_to_minio
AIRFLOW_CTX_TASK_ID=generate_and_upload_to_s3
AIRFLOW_CTX_EXECUTION_DATE=2020-01-13T00:00:00+00:00
AIRFLOW_CTX_DAG_RUN_ID=scheduled__2020-01-13T00:00:00+00:00
[2021-03-03 21:08:22,764] {base_aws.py:362} INFO - Airflow Connection: aws_conn_id=local_minio
[2021-03-03 21:08:22,769] {base_aws.py:164} INFO - Credentials retrieved from extra_config
[2021-03-03 21:08:22,769] {base_aws.py:81} INFO - Creating session with aws_access_key_id=minio-access-key region_name=None
[2021-03-03 21:08:22,778] {base_aws.py:151} INFO - role_arn is None
[2021-03-03 21:08:22,812] {taskinstance.py:1455} ERROR - The key my-test-file.txt already exists.
Traceback (most recent call last):
  File "/home/airflow/.local/lib/python3.6/site-packages/airflow/models/taskinstance.py", line 1112, in _run_raw_task
    self._prepare_and_execute_task_with_callbacks(context, task)
  File "/home/airflow/.local/lib/python3.6/site-packages/airflow/models/taskinstance.py", line 1285, in _prepare_and_execute_task_with_callbacks
    result = self._execute_task(context, task_copy)
  File "/home/airflow/.local/lib/python3.6/site-packages/airflow/models/taskinstance.py", line 1315, in _execute_task
    result = task_copy.execute(context=context)
  File "/home/airflow/.local/lib/python3.6/site-packages/airflow/operators/python.py", line 117, in execute
    return_value = self.execute_callable()
  File "/home/airflow/.local/lib/python3.6/site-packages/airflow/operators/python.py", line 128, in execute_callable
    return self.python_callable(*self.op_args, **self.op_kwargs)
  File "/opt/airflow/dags/save_to_minio/main.py", line 29, in write_text_file
    s3.load_file("/tmp/test.txt", key="my-test-file.txt", bucket_name="my-first-bucket")
  File "/home/airflow/.local/lib/python3.6/site-packages/airflow/providers/amazon/aws/hooks/s3.py", line 61, in wrapper
    return func(*bound_args.args, **bound_args.kwargs)
  File "/home/airflow/.local/lib/python3.6/site-packages/airflow/providers/amazon/aws/hooks/s3.py", line 90, in wrapper
    return func(*bound_args.args, **bound_args.kwargs)
  File "/home/airflow/.local/lib/python3.6/site-packages/airflow/providers/amazon/aws/hooks/s3.py", line 490, in load_file
    raise ValueError(f"The key {key} already exists.")
ValueError: The key my-test-file.txt already exists.
[2021-03-03 21:08:22,814] {taskinstance.py:1503} INFO - Marking task as FAILED. dag_id=save_to_minio, task_id=generate_and_upload_to_s3, execution_date=20200113T000000, start_date=20210303T210822, end_date=20210303T210822
[2021-03-03 21:08:22,851] {local_task_job.py:146} INFO - Task exited with return code 1
